ERROR:root:Exception occurred
Traceback (most recent call last):
  File "C:\Users\gabri\AppData\Local\Temp\ipykernel_17124\3938189099.py", line 10, in <module>
    result = x / y
             ~~^~~
ZeroDivisionError: division by zero
ERROR:root:Exception occurred
Traceback (most recent call last):
  File "C:\Users\gabri\AppData\Local\Temp\ipykernel_17124\3119706326.py", line 9, in <module>
    raise ValueError("Erro de exemplo")
ValueError: Erro de exemplo
ERROR:root:Exception occurred
Traceback (most recent call last):
  File "C:\Users\gabri\AppData\Local\Temp\ipykernel_17124\3938189099.py", line 10, in <module>
    result = x / y
             ~~^~~
ZeroDivisionError: division by zero
